Traceback (most recent call last):
  File "bot.py", line 20, in <module>
    client = TelegramClient('penguin', api_id, api_hash, proxy=(socks.SOCKS5, '127.0.0.1', 7891)).start(bot_token=bot_token)
  File "/usr/local/lib/python3.8/site-packages/telethon/client/auth.py", line 128, in start
    else self.loop.run_until_complete(coro)
  File "/usr/local/lib/python3.8/asyncio/base_events.py", line 608, in run_until_complete
    return future.result()
  File "/usr/local/lib/python3.8/site-packages/telethon/client/auth.py", line 135, in _start
    await self.connect()
  File "/usr/local/lib/python3.8/site-packages/telethon/client/telegrambaseclient.py", line 555, in connect
    self.session.auth_key = self._sender.auth_key
  File "/usr/local/lib/python3.8/site-packages/telethon/sessions/sqlite.py", line 180, in auth_key
    self._update_session_table()
  File "/usr/local/lib/python3.8/site-packages/telethon/sessions/sqlite.py", line 194, in _update_session_table
    c.execute('delete from sessions')
sqlite3.OperationalError: database is locked
An open stream object is being garbage collected; call "stream.close()" explicitly.
Task was destroyed but it is pending!
task: <Task pending name='Task-4' coro=<MTProtoSender._send_loop() running at /usr/local/lib/python3.8/site-packages/telethon/network/mtprotosender.py:462> wait_for=<Future pending cb=[<TaskWakeupMethWrapper object at 0x7fd964056880>()]>>
Task was destroyed but it is pending!
task: <Task pending name='Task-5' coro=<MTProtoSender._recv_loop() running at /usr/local/lib/python3.8/site-packages/telethon/network/mtprotosender.py:505> wait_for=<Future pending cb=[<TaskWakeupMethWrapper object at 0x7fd964056820>()]>>
Task was destroyed but it is pending!
task: <Task pending name='Task-2' coro=<Connection._send_loop() running at /usr/local/lib/python3.8/site-packages/telethon/network/connection/connection.py:316> wait_for=<Future pending cb=[<TaskWakeupMethWrapper object at 0x7fd96404e3d0>()]>>
Task was destroyed but it is pending!
task: <Task pending name='Task-3' coro=<Connection._recv_loop() running at /usr/local/lib/python3.8/site-packages/telethon/network/connection/connection.py:335> wait_for=<Future pending cb=[<TaskWakeupMethWrapper object at 0x7fd96404e370>()]>>
Exception ignored in: <coroutine object Connection._recv_loop at 0x7fd9643b44c0>
RuntimeError: coroutine ignored GeneratorExit
